{\rtf1\ansi\ansicpg1252\cocoartf2638
\cocoatextscaling0\cocoaplatform0{\fonttbl\f0\fnil\fcharset0 Menlo-Regular;}
{\colortbl;\red255\green255\blue255;\red0\green0\blue0;}
{\*\expandedcolortbl;;\csgray\c0;}
\margl1440\margr1440\vieww11520\viewh8400\viewkind0
\pard\tx560\tx1120\tx1680\tx2240\tx2800\tx3360\tx3920\tx4480\tx5040\tx5600\tx6160\tx6720\pardirnatural\partightenfactor0

\f0\fs22 \cf2 \CocoaLigature0 Last login: Wed Jun 15 22:02:45 on ttys002\
cd '/Users/audiumadmin/Documents/GitHub/DSS-Bridge/' && '/usr/local/bin/python3'  '/Users/audiumadmin/Documents/GitHub/DSS-Bridge/DSS_Bridge.py'  && echo Exit status: $? && exit 1\
audiumadmin@AudiumsacStudio ~ % cd '/Users/audiumadmin/Documents/GitHub/DSS-Bridge/' && '/usr/local/bin/python3'  '/Users/audiumadmin/Documents/GitHub/DSS-Bridge/DSS_Bridge.py'  && echo Exit status: $? && exit 1\
AudiumsacStudio\
192.168.42.90\
B\
opened: /dev/cu.usbmodem3111101\
A\
opened: /dev/cu.usbmodem3111301\
X\
opened: /dev/cu.usbmodem3111201\
L\
opened: /dev/cu.usbmodem31114101\
X0001000000000000000100000000000000010000000000000001000000000000\
\
X0000100000000000000010000000000000001000000000000000100000000000\
\
X0000010000000000000001000000000000000100000000000000010000000000\
\
X1000000000000000100000000000000010000000000000001000000000000000\
\
----------------------------------------\
Exception occurred during processing of request from ('192.168.42.90', 55500)\
Traceback (most recent call last):\
  File "/Library/Frameworks/Python.framework/Versions/3.9/lib/python3.9/socketserver.py", line 683, in process_request_thread\
    self.finish_request(request, client_address)\
  File "/Library/Frameworks/Python.framework/Versions/3.9/lib/python3.9/socketserver.py", line 360, in finish_request\
    self.RequestHandlerClass(request, client_address, self)\
  File "/Library/Frameworks/Python.framework/Versions/3.9/lib/python3.9/socketserver.py", line 747, in __init__\
    self.handle()\
  File "/Library/Frameworks/Python.framework/Versions/3.9/lib/python3.9/site-packages/pythonosc/osc_server.py", line 29, in handle\
    self.server.dispatcher.call_handlers_for_packet(self.request[0], self.client_address)\
  File "/Library/Frameworks/Python.framework/Versions/3.9/lib/python3.9/site-packages/pythonosc/dispatcher.py", line 194, in call_handlers_for_packet\
    handler.invoke(client_address, timed_msg.message)\
  File "/Library/Frameworks/Python.framework/Versions/3.9/lib/python3.9/site-packages/pythonosc/dispatcher.py", line 57, in invoke\
    self.callback(message.address, *message)\
  File "/Users/audiumadmin/Documents/GitHub/DSS-Bridge/DSS_Bridge.py", line 170, in DSS_switcher_handler\
    DSS_State = s.readline().decode().strip()\
  File "/Library/Frameworks/Python.framework/Versions/3.9/lib/python3.9/site-packages/serial/serialposix.py", line 595, in read\
    raise SerialException(\
serial.serialutil.SerialException: device reports readiness to read but returned no data (device disconnected or multiple access on port?)\
----------------------------------------\
X0100000000000000010000000000000001000000000000000100000000000000\
\
----------------------------------------\
Exception occurred during processing of request from ('192.168.42.90', 55500)\
Traceback (most recent call last):\
  File "/Library/Frameworks/Python.framework/Versions/3.9/lib/python3.9/socketserver.py", line 683, in process_request_thread\
    self.finish_request(request, client_address)\
  File "/Library/Frameworks/Python.framework/Versions/3.9/lib/python3.9/socketserver.py", line 360, in finish_request\
    self.RequestHandlerClass(request, client_address, self)\
  File "/Library/Frameworks/Python.framework/Versions/3.9/lib/python3.9/socketserver.py", line 747, in __init__\
    self.handle()\
  File "/Library/Frameworks/Python.framework/Versions/3.9/lib/python3.9/site-packages/pythonosc/osc_server.py", line 29, in handle\
    self.server.dispatcher.call_handlers_for_packet(self.request[0], self.client_address)\
  File "/Library/Frameworks/Python.framework/Versions/3.9/lib/python3.9/site-packages/pythonosc/dispatcher.py", line 194, in call_handlers_for_packet\
    handler.invoke(client_address, timed_msg.message)\
  File "/Library/Frameworks/Python.framework/Versions/3.9/lib/python3.9/site-packages/pythonosc/dispatcher.py", line 57, in invoke\
    self.callback(message.address, *message)\
  File "/Users/audiumadmin/Documents/GitHub/DSS-Bridge/DSS_Bridge.py", line 170, in DSS_switcher_handler\
    DSS_State = s.readline().decode().strip()\
  File "/Library/Frameworks/Python.framework/Versions/3.9/lib/python3.9/site-packages/serial/serialposix.py", line 595, in read\
    raise SerialException(\
serial.serialutil.SerialException: device reports readiness to read but returned no data (device disconnected or multiple access on port?)\
----------------------------------------\
X0010000000000000001000000000000000100000000000000010000000000000\
\
X0001000000000000000100000000000000010000000000000001000000000000\
\
X0000100000000000000010000000000000001000000000000000100000000000\
\
X0000010000000000000001000000000000000100000000000000010000000000\
\
X1000000000000000100000000000000010000000000000001000000000000000\
\
X0100000000000000010000000000000001000000000000000100000000000000\
\
X0010000000000000001000000000000000100000000000000010000000000000\
\
----------------------------------------\
Exception occurred during processing of request from ('192.168.42.90', 55500)\
Traceback (most recent call last):\
  File "/Library/Frameworks/Python.framework/Versions/3.9/lib/python3.9/socketserver.py", line 683, in process_request_thread\
    self.finish_request(request, client_address)\
  File "/Library/Frameworks/Python.framework/Versions/3.9/lib/python3.9/socketserver.py", line 360, in finish_request\
    self.RequestHandlerClass(request, client_address, self)\
  File "/Library/Frameworks/Python.framework/Versions/3.9/lib/python3.9/socketserver.py", line 747, in __init__\
    self.handle()\
  File "/Library/Frameworks/Python.framework/Versions/3.9/lib/python3.9/site-packages/pythonosc/osc_server.py", line 29, in handle\
    self.server.dispatcher.call_handlers_for_packet(self.request[0], self.client_address)\
  File "/Library/Frameworks/Python.framework/Versions/3.9/lib/python3.9/site-packages/pythonosc/dispatcher.py", line 194, in call_handlers_for_packet\
    handler.invoke(client_address, timed_msg.message)\
  File "/Library/Frameworks/Python.framework/Versions/3.9/lib/python3.9/site-packages/pythonosc/dispatcher.py", line 57, in invoke\
    self.callback(message.address, *message)\
  File "/Users/audiumadmin/Documents/GitHub/DSS-Bridge/DSS_Bridge.py", line 170, in DSS_switcher_handler\
    DSS_State = s.readline().decode().strip()\
  File "/Library/Frameworks/Python.framework/Versions/3.9/lib/python3.9/site-packages/serial/serialposix.py", line 595, in read\
    raise SerialException(\
serial.serialutil.SerialException: device reports readiness to read but returned no data (device disconnected or multiple access on port?)\
----------------------------------------\
X0001000000000000000100000000000000010000000000000001000000000000\
\
X0000100000000000000010000000000000001000000000000000100000000000\
\
X0000010000000000000001000000000000000100000000000000010000000000\
\
X1000000000000000100000000000000010000000000000001000000000000000\
\
X0100000000000000010000000000000001000000000000000100000000000000\
\
X0010000000000000001000000000000000100000000000000010000000000000\
\
X0001000000000000000100000000000000010000000000000001000000000000\
\
X0000100000000000000010000000000000001000000000000000100000000000\
\
X0000010000000000000001000000000000000100000000000000010000000000\
\
\
\
ETC ETC}